Workbook

Sheet Planilha1
B2: Símbolos não terminais original | C2: Escolhido | E2: Símbolos terminais originais
B3: Programa | C3: A | E3: algoritmo | F3: a
B4: BlocoVariaveis | C4: B | E4: inicio | F4: b
B5: BlocoComandos | C5: C | E5: fim | F5: c
B6: ProcedimentoFuncao | C6: D | E6: variaveis | F6: d
B7: DeclaraProcedimento | C7: E | E7: e | F7: e
B8: DeclaraFuncao | C8: F | E8: real | F8: f
B9: Parametros | C9: G | E9: caractere | F9: g
B10: DeclaraParametros | C10: H | E10: logico | F10: h
B11: DeclaraIdentificador | C11: I | E11: vetor | F11: i
B12: Declaracoes | C12: J | E12: matriz | F12: j
B13: DeclaraVariaveis | C13: K | E13: tipo | F13: k
B14: DeclaraTipo | C14: L | E14: funcao | F14: l
... B25: Fator | C25: W | E25: repita | F25: w
C26: X | E26: leia | F26: x
C27: Y | E27: imprima | F27: y
C28: Z | E28: TRUE | F28: z
E29: FALSE | F29: 1
E30: inteiro | F30: 2
E31: ou | F31: 3
E32: não | F32: 4
E33: div | F33: 5
E34: <> | F34: 6
E35: >= | F35: 7
E36: <= | F36: 8
E37: <- | F37: 9
E38: identificador | F38: 0
E39: ;
E40: ,
E41: :
E42: .
E43: [
E44: ]
E45: (
E46: )
E47: =
E48: >
E49: <
E50: +
... E53: /
...

Sheet LL1 Parser Table
B2: FIRST | C2: FOLLOW | D2: Nonterminal | E2: algoritmo | F2: identificador | G2: ; | H2: . | I2: procedimento | J2: funcao | K2: : | L2: ( | M2: ) | N2: variaveis | O2: tipo | P2: = | Q2: [ | R2: ] | S2: , | T2: vetor | U2: matriz | V2: numero_inteiro | W2: inteiro | X2: real | Y2: caractere | Z2: logico | AA2: inicio | AB2: fim | AC2: <- | AD2: se | AE2: entao | AF2: senao | AG2: enquanto | AH2: faca | AI2: para | AJ2: de | AK2: ate | AL2: passo | AM2: repita | AN2: leia | AO2: imprima | AP2: <> | AQ2: < | AR2: <= | AS2: >= | AT2: > | AU2: + | AV2: - | AW2: ou | AX2: * | AY2: / | AZ2: div | BA2: e | BB2: nao | BC2: numero_real | BD2: TRUE | BE2: FALSE | BF2: string | BG2: $
B3: {algoritmo} | C3: {$} | D3: Programa | E3: Programa -> algoritmo identificador ; BlocoVariaveis ProcedimentoFuncao BlocoComandos .
B4: {'',procedimento,funcao} | C4: {inicio} | D4: ProcedimentoFuncao | I4: ProcedimentoFuncao -> DeclaraProcedimento ProcedimentoFuncao | J4: ProcedimentoFuncao -> DeclaraFuncao ProcedimentoFuncao | AA4: ProcedimentoFuncao -> ''
B5: {procedimento} | C5: {inicio,procedimento,funcao} | D5: DeclaraProcedimento | I5: DeclaraProcedimento -> procedimento identificador Parametros ; DeclaraParametros BlocoVariaveis BlocoComandos ;
B6: {funcao} | C6: {inicio,procedimento,funcao} | D6: DeclaraFuncao | J6: DeclaraFuncao -> funcao identificador Parametros : TipoBasico ; DeclaraParametros BlocoVariaveis BlocoComandos ;
B7: {(,''} | C7: {;,:} | D7: Parametros | G7: Parametros -> '' | K7: Parametros -> '' | L7: Parametros -> ( DeclaraIdentificador )
B8: {'',tipo,inteiro,real,caractere,logico,identificador} | C8: {variaveis,inicio,procedimento,funcao} | D8: DeclaraParametros | F8: DeclaraParametros -> Declaracoes | I8: DeclaraParametros -> '' | J8: DeclaraParametros -> '' | N8: DeclaraParametros -> '' | O8: DeclaraParametros -> Declaracoes | W8: DeclaraParametros -> Declaracoes | X8: DeclaraParametros -> Declaracoes | Y8: DeclaraParametros -> Declaracoes | Z8: DeclaraParametros -> Declaracoes | AA8: DeclaraParametros -> ''
B9: {variaveis,''} | C9: {$,procedimento,funcao,inicio} | D9: BlocoVariaveis | I9: BlocoVariaveis -> '' | J9: BlocoVariaveis -> '' | N9: BlocoVariaveis -> variaveis Declaracoes | AA9: BlocoVariaveis -> '' | BG9: BlocoVariaveis -> ''
B10: {tipo,inteiro,real,caractere,logico,identificador} | C10: {variaveis,inicio,procedimento,funcao,$} | D10: Declaracoes | F10: Declaracoes -> Declarations DeclaracoesBonus | O10: Declaracoes -> Declarations DeclaracoesBonus | W10: Declaracoes -> Declarations DeclaracoesBonus | X10: Declaracoes -> Declarations DeclaracoesBonus | Y10: Declaracoes -> Declarations DeclaracoesBonus | Z10: Declaracoes -> Declarations DeclaracoesBonus
B11: {'',tipo,inteiro,real,caractere,logico,identificador} | C11: {variaveis,inicio,procedimento,funcao,$} | D11: DeclaracoesBonus | F11: DeclaracoesBonus -> Declaracoes | I11: DeclaracoesBonus -> '' | J11: DeclaracoesBonus -> '' | N11: DeclaracoesBonus -> '' | O11: DeclaracoesBonus -> Declaracoes | W11: DeclaracoesBonus -> Declaracoes | X11: DeclaracoesBonus -> Declaracoes | Y11: DeclaracoesBonus -> Declaracoes | Z11: DeclaracoesBonus -> Declaracoes | AA11: DeclaracoesBonus -> '' | BG11: DeclaracoesBonus -> ''
B12: {tipo,inteiro,real,caractere,logico,identificador} | C12: {variaveis,inicio,procedimento,funcao,$,tipo,inteiro,real,caractere,logico,identificador} | D12: Declarations | F12: Declarations -> DeclaraVariaveis | O12: Declarations -> DeclaraTipo | W12: Declarations -> DeclaraVariaveis | X12: Declarations -> DeclaraVariaveis | Y12: Declarations -> DeclaraVariaveis | Z12: Declarations -> DeclaraVariaveis
B13: {tipo} | C13: {variaveis,inicio,procedimento,funcao,$,tipo,inteiro,real,caractere,logico,identificador} | D13: DeclaraTipo | O13: DeclaraTipo -> tipo identificador = VetorMatriz [ Dimensao ] TipoBasico ;
B14: {inteiro,real,caractere,logico,identificador} | C14: {variaveis,inicio,procedimento,funcao,$,tipo,inteiro,real,caractere,logico,identificador} | D14: DeclaraVariaveis | F14: DeclaraVariaveis -> TipoBasico : DeclaraIdentificador ; | W14: DeclaraVariaveis -> TipoBasico : DeclaraIdentificador ; | X14: DeclaraVariaveis -> TipoBasico : DeclaraIdentificador ; | Y14: DeclaraVariaveis -> TipoBasico : DeclaraIdentificador ; | Z14: DeclaraVariaveis -> TipoBasico : DeclaraIdentificador ;
B15: {identificador} | C15: {),;} | D15: DeclaraIdentificador | F15: DeclaraIdentificador -> identificador DeclaraIdentificadorBonus
B16: {,,''} | C16: {),;} | D16: DeclaraIdentificadorBonus | G16: DeclaraIdentificadorBonus -> '' | M16: DeclaraIdentificadorBonus -> '' | S16: DeclaraIdentificadorBonus -> , DeclaraIdentificador
B17: {vetor,matriz} | C17: {[} | D17: VetorMatriz | T17: VetorMatriz -> vetor | U17: VetorMatriz -> matriz
B18: {numero_inteiro} | C18: {]} | D18: Dimensao | V18: Dimensao -> numero_inteiro : numero_inteiro DimensaoBonus
B19: {,,''} | C19: {]} | D19: DimensaoBonus | R19: DimensaoBonus -> '' | S19: DimensaoBonus -> , Dimensao
B20: {inteiro,real,caractere,logico,identificador} | C20: {;,:} | D20: TipoBasico | F20: TipoBasico -> identificador | W20: TipoBasico -> inteiro | X20: TipoBasico -> real | Y20: TipoBasico -> caractere | Z20: TipoBasico -> logico
B21: {inicio} | C21: {.,;} | D21: BlocoComandos | AA21: BlocoComandos -> inicio ListaComandos fim
B22: {identificador,se,enquanto,para,repita,leia,imprima} | C22: {fim,senao,;,ate} | D22: ListaComandos | F22: ListaComandos -> Comandos ; ListaComandosBonus | AD22: ListaComandos -> Comandos ; ListaComandosBonus | AG22: ListaComandos -> Comandos ; ListaComandosBonus | AI22: ListaComandos -> Comandos ; ListaComandosBonus | AM22: ListaComandos -> Comandos ; ListaComandosBonus | AN22: ListaComandos -> Comandos ; ListaComandosBonus | AO22: ListaComandos -> Comandos ; ListaComandosBonus
B23: {'',identificador,se,enquanto,para,repita,leia,imprima} | C23: {fim,senao,;,ate} | D23: ListaComandosBonus | F23: ListaComandosBonus -> ListaComandos | G23: ListaComandosBonus -> '' | AB23: ListaComandosBonus -> '' | AD23: ListaComandosBonus -> ListaComandos | AF23: ListaComandosBonus -> '' | AG23: ListaComandosBonus -> ListaComandos | AI23: ListaComandosBonus -> ListaComandos | AK23: ListaComandosBonus -> '' | AM23: ListaComandosBonus -> ListaComandos | AN23: ListaComandosBonus -> ListaComandos | AO23: ListaComandosBonus -> ListaComandos
B24: {identificador,se,enquanto,para,repita,leia,imprima} | C24: {;} | D24: Comandos | F24: Comandos -> identificador CommandsIdentifier | AD24: Comandos -> se Expressao entao ListaComandos ElseIf fim se | AG24: Comandos -> enquanto Expressao faca ListaComandos fim enquanto | AI24: Comandos -> para identificador de Expressao ate Expressao StepFor faca ListaComandos fim para | AM24: Comandos -> repita ListaComandos ate Expressao | AN24: Comandos -> leia ( Variavel ) | AO24: Comandos -> imprima ( ExprIter )
B25: {'',(,<-,[} | C25: {;} | D25: CommandsIdentifier | G25: CommandsIdentifier -> '' | L25: CommandsIdentifier -> ( ExprIter ) | Q25: CommandsIdentifier -> [ ExprIter ] <- Expressao | AC25: CommandsIdentifier -> <- Expressao
B26: {senao,''} | C26: {fim} | D26: ElseIf | AB26: ElseIf -> '' | AF26: ElseIf -> senao ListaComandos
B27: {passo,''} | C27: {faca} | D27: StepFor | AH27: StepFor -> '' | AL27: StepFor -> passo Expressao
B28: {+,-,'',=,<>,<,<=,>=,>,(,nao,numero_inteiro,numero_real,verdadeiro,falso,string,identificador} | C28: {;,entao,faca,ate,passo,),,,]} | D28: Expressao | F28: Expressao -> ExpressaoSimples ExpressaoNew | G28: Expressao -> ExpressaoSimples ExpressaoNew | L28: Expressao -> ExpressaoSimples ExpressaoNew | M28: Expressao -> ExpressaoSimples ExpressaoNew | P28: Expressao -> ExpressaoSimples ExpressaoNew | R28: Expressao -> ExpressaoSimples ExpressaoNew | S28: Expressao -> ExpressaoSimples ExpressaoNew | V28: Expressao -> ExpressaoSimples ExpressaoNew | AE28: Expressao -> ExpressaoSimples ExpressaoNew | AH28: Expressao -> ExpressaoSimples ExpressaoNew | AK28: Expressao -> ExpressaoSimples ExpressaoNew | AL28: Expressao -> ExpressaoSimples ExpressaoNew | AP28: Expressao -> ExpressaoSimples ExpressaoNew | AQ28: Expressao -> ExpressaoSimples ExpressaoNew | AR28: Expressao -> ExpressaoSimples ExpressaoNew | AS28: Expressao -> ExpressaoSimples ExpressaoNew | AT28: Expressao -> ExpressaoSimples ExpressaoNew | AU28: Expressao -> ExpressaoSimples ExpressaoNew | AV28: Expressao -> ExpressaoSimples ExpressaoNew | BB28: Expressao -> ExpressaoSimples ExpressaoNew | BC28: Expressao -> ExpressaoSimples ExpressaoNew | BD28: Expressao -> ExpressaoSimples ExpressaoNew | BE28: Expressao -> ExpressaoSimples ExpressaoNew | BF28: Expressao -> ExpressaoSimples ExpressaoNew
B29: {=,<>,<,<=,>=,>,''} | C29: {;,entao,faca,ate,passo,),,,]} | D29: ExpressaoNew | G29: ExpressaoNew -> '' | M29: ExpressaoNew -> '' | P29: ExpressaoNew -> = ExpressaoSimples ExpressaoNew | R29: ExpressaoNew -> '' | S29: ExpressaoNew -> '' | AE29: ExpressaoNew -> '' | AH29: ExpressaoNew -> '' | AK29: ExpressaoNew -> '' | AL29: ExpressaoNew -> '' | AP29: ExpressaoNew -> <> ExpressaoSimples ExpressaoNew | AQ29: ExpressaoNew -> < ExpressaoSimples ExpressaoNew | AR29: ExpressaoNew -> <= ExpressaoSimples ExpressaoNew | AS29: ExpressaoNew -> >= ExpressaoSimples ExpressaoNew | AT29: ExpressaoNew -> > ExpressaoSimples ExpressaoNew
B30: {+,-,'',(,nao,numero_inteiro,numero_real,verdadeiro,falso,string,identificador} | C30: {=,<>,<,<=,>=,>,;,entao,faca,ate,passo,),,,]} | D30: ExpressaoSimples | F30: ExpressaoSimples -> Signal Termo ExpressaoSimplesNew | G30: ExpressaoSimples -> Signal Termo ExpressaoSimplesNew | L30: ExpressaoSimples -> Signal Termo ExpressaoSimplesNew | M30: ExpressaoSimples -> Signal Termo ExpressaoSimplesNew | P30: ExpressaoSimples -> Signal Termo ExpressaoSimplesNew | R30: ExpressaoSimples -> Signal Termo ExpressaoSimplesNew | S30: ExpressaoSimples -> Signal Termo ExpressaoSimplesNew | V30: ExpressaoSimples -> Signal Termo ExpressaoSimplesNew | AE30: ExpressaoSimples -> Signal Termo ExpressaoSimplesNew | AH30: ExpressaoSimples -> Signal Termo ExpressaoSimplesNew | AK30: ExpressaoSimples -> Signal Termo ExpressaoSimplesNew | AL30: ExpressaoSimples -> Signal Termo ExpressaoSimplesNew | AP30: ExpressaoSimples -> Signal Termo ExpressaoSimplesNew | AQ30: ExpressaoSimples -> Signal Termo ExpressaoSimplesNew | AR30: ExpressaoSimples -> Signal Termo ExpressaoSimplesNew | AS30: ExpressaoSimples -> Signal Termo ExpressaoSimplesNew | AT30: ExpressaoSimples -> Signal Termo ExpressaoSimplesNew | AU30: ExpressaoSimples -> Signal Termo ExpressaoSimplesNew | AV30: ExpressaoSimples -> Signal Termo ExpressaoSimplesNew | BB30: ExpressaoSimples -> Signal Termo ExpressaoSimplesNew | BC30: ExpressaoSimples -> Signal Termo ExpressaoSimplesNew | BD30: ExpressaoSimples -> Signal Termo ExpressaoSimplesNew | BE30: ExpressaoSimples -> Signal Termo ExpressaoSimplesNew | BF30: ExpressaoSimples -> Signal Termo ExpressaoSimplesNew
B31: {+,-,''} | C31: {(,nao,numero_inteiro,numero_real,verdadeiro,falso,string,identificador} | D31: Signal | F31: Signal -> '' | L31: Signal -> '' | V31: Signal -> '' | AU31: Signal -> + | AV31: Signal -> - | BB31: Signal -> '' | BC31: Signal -> '' | BD31: Signal -> '' | BE31: Signal -> '' | BF31: Signal -> ''
B32: {+,-,ou,''} | C32: {=,<>,<,<=,>=,>,;,entao,faca,ate,passo,),,,]} | D32: ExpressaoSimplesNew | G32: ExpressaoSimplesNew -> '' | M32: ExpressaoSimplesNew -> '' | P32: ExpressaoSimplesNew -> '' | R32: ExpressaoSimplesNew -> '' | S32: ExpressaoSimplesNew -> '' | AE32: ExpressaoSimplesNew -> '' | AH32: ExpressaoSimplesNew -> '' | AK32: ExpressaoSimplesNew -> '' | AL32: ExpressaoSimplesNew -> '' | AP32: ExpressaoSimplesNew -> '' | AQ32: ExpressaoSimplesNew -> '' | AR32: ExpressaoSimplesNew -> '' | AS32: ExpressaoSimplesNew -> '' | AT32: ExpressaoSimplesNew -> '' | AU32: ExpressaoSimplesNew -> + Termo ExpressaoSimplesNew | AV32: ExpressaoSimplesNew -> - Termo ExpressaoSimplesNew | AW32: ExpressaoSimplesNew -> ou Termo ExpressaoSimplesNew
B33: {(,nao,numero_inteiro,numero_real,verdadeiro,falso,string,identificador} | C33: {+,-,ou,=,<>,<,<=,>=,>,;,entao,faca,ate,passo,),,,]} | D33: Termo | F33: Termo -> Fator TermoNew | L33: Termo -> Fator TermoNew | V33: Termo -> Fator TermoNew | BB33: Termo -> Fator TermoNew | BC33: Termo -> Fator TermoNew | BD33: Termo -> Fator TermoNew | BE33: Termo -> Fator TermoNew | BF33: Termo -> Fator TermoNew
B34: {*,/,div,e,''} | C34: {+,-,ou,=,<>,<,<=,>=,>,;,entao,faca,ate,passo,),,,]} | D34: TermoNew | G34: TermoNew -> '' | M34: TermoNew -> '' | P34: TermoNew -> '' | R34: TermoNew -> '' | S34: TermoNew -> '' | AE34: TermoNew -> '' | AH34: TermoNew -> '' | AK34: TermoNew -> '' | AL34: TermoNew -> '' | AP34: TermoNew -> '' | AQ34: TermoNew -> '' | AR34: TermoNew -> '' | AS34: TermoNew -> '' | AT34: TermoNew -> '' | AU34: TermoNew -> '' | AV34: TermoNew -> '' | AW34: TermoNew -> '' | AX34: TermoNew -> * Fator TermoNew | AY34: TermoNew -> / Fator TermoNew | AZ34: TermoNew -> div Fator TermoNew | BA34: TermoNew -> e Fator TermoNew
B35: {(,nao,numero_inteiro,numero_real,verdadeiro,falso,string,identificador} | C35: {*,/,div,e,+,-,ou,=,<>,<,<=,>=,>,;,entao,faca,ate,passo,),,,]} | D35: Fator | F35: Fator -> identificador IdentifierVariable | L35: Fator -> ( Expressao ) | V35: Fator -> numero_inteiro | BB35: Fator -> nao Fator | BC35: Fator -> numero_real | BD35: Fator -> verdadeiro | BE35: Fator -> falso | BF35: Fator -> string
B36: {(,[,''} | C36: {*,/,div,e,+,-,ou,=,<>,<,<=,>=,>,;,entao,faca,ate,passo,),,,]} | D36: IdentifierVariable | G36: IdentifierVariable -> VariableExp | L36: IdentifierVariable -> ( ExprIter ) | M36: IdentifierVariable -> VariableExp | P36: IdentifierVariable -> VariableExp | Q36: IdentifierVariable -> VariableExp | R36: IdentifierVariable -> VariableExp | S36: IdentifierVariable -> VariableExp | AE36: IdentifierVariable -> VariableExp | AH36: IdentifierVariable -> VariableExp | AK36: IdentifierVariable -> VariableExp | AL36: IdentifierVariable -> VariableExp | AP36: IdentifierVariable -> VariableExp | AQ36: IdentifierVariable -> VariableExp | AR36: IdentifierVariable -> VariableExp | AS36: IdentifierVariable -> VariableExp | AT36: IdentifierVariable -> VariableExp | AU36: IdentifierVariable -> VariableExp | AV36: IdentifierVariable -> VariableExp | AW36: IdentifierVariable -> VariableExp | AX36: IdentifierVariable -> VariableExp | AY36: IdentifierVariable -> VariableExp | AZ36: IdentifierVariable -> VariableExp | BA36: IdentifierVariable -> VariableExp
B37: {identificador} | C37: {)} | D37: Variavel | F37: Variavel -> identificador VariableExp
B38: {[,''} | C38: {*,/,div,e,+,-,ou,=,<>,<,<=,>=,>,;,entao,faca,ate,passo,),,,]} | D38: VariableExp | G38: VariableExp -> '' | M38: VariableExp -> '' | P38: VariableExp -> '' | Q38: VariableExp -> [ ExprIter ] | R38: VariableExp -> '' | S38: VariableExp -> '' | AE38: VariableExp -> '' | AH38: VariableExp -> '' | AK38: VariableExp -> '' | AL38: VariableExp -> '' | AP38: VariableExp -> '' | AQ38: VariableExp -> '' | AR38: VariableExp -> '' | AS38: VariableExp -> '' | AT38: VariableExp -> '' | AU38: VariableExp -> '' | AV38: VariableExp -> '' | AW38: VariableExp -> '' | AX38: VariableExp -> '' | AY38: VariableExp -> '' | AZ38: VariableExp -> '' | BA38: VariableExp -> ''
B39: {+,-,'',=,<>,<,<=,>=,>,,,(,nao,numero_inteiro,numero_real,verdadeiro,falso,string,identificador} | C39: {),]} | D39: ExprIter | F39: ExprIter -> Expressao ExprIterBonus | L39: ExprIter -> Expressao ExprIterBonus | M39: ExprIter -> Expressao ExprIterBonus | P39: ExprIter -> Expressao ExprIterBonus | R39: ExprIter -> Expressao ExprIterBonus | S39: ExprIter -> Expressao ExprIterBonus | V39: ExprIter -> Expressao ExprIterBonus | AP39: ExprIter -> Expressao ExprIterBonus | AQ39: ExprIter -> Expressao ExprIterBonus | AR39: ExprIter -> Expressao ExprIterBonus | AS39: ExprIter -> Expressao ExprIterBonus | AT39: ExprIter -> Expressao ExprIterBonus | AU39: ExprIter -> Expressao ExprIterBonus | AV39: ExprIter -> Expressao ExprIterBonus | BB39: ExprIter -> Expressao ExprIterBonus | BC39: ExprIter -> Expressao ExprIterBonus | BD39: ExprIter -> Expressao ExprIterBonus | BE39: ExprIter -> Expressao ExprIterBonus | BF39: ExprIter -> Expressao ExprIterBonus
B40: {,,''} | C40: {),]} | D40: ExprIterBonus | M40: ExprIterBonus -> '' | R40: ExprIterBonus -> '' | S40: ExprIterBonus -> , ExprIter

Sheet Format1
B1: ='LL1 Parser Table'!D2 -> Nonterminal | C1: ='LL1 Parser Table'!E2 -> algoritmo | D1: ='LL1 Parser Table'!F2 -> identificador | E1: ='LL1 Parser Table'!G2 -> ; | F1: ='LL1 Parser Table'!H2 -> . | G1: ='LL1 Parser Table'!I2 -> procedimento | H1: ='LL1 Parser Table'!J2 -> funcao | I1: ='LL1 Parser Table'!K2 -> : | ... BE1: ='LL1 Parser Table'!BG2 -> $
A2: 1 | B2: ='LL1 Parser Table'!D3 -> Programa | C2: =IF(ISBLANK('LL1 Parser Table'!E3),"ERRO",'LL1 Parser Table'!E3) -> Programa -> algoritmo identificador ; BlocoVariaveis ProcedimentoFuncao BlocoComandos . | D2: =IF(ISBLANK('LL1 Parser Table'!F3),"ERRO",'LL1 Parser Table'!F3) -> ERRO | E2: =IF(ISBLANK('LL1 Parser Table'!G3),"ERRO",'LL1 Parser Table'!G3) -> ERRO | F2: =IF(ISBLANK('LL1 Parser Table'!H3),"ERRO",'LL1 Parser Table'!H3) -> ERRO | G2: =IF(ISBLANK('LL1 Parser Table'!I3),"ERRO",'LL1 Parser Table'!I3) -> ERRO | H2: =IF(ISBLANK('LL1 Parser Table'!J3),"ERRO",'LL1 Parser Table'!J3) -> ERRO | I2: =IF(ISBLANK('LL1 Parser Table'!K3),"ERRO",'LL1 Parser Table'!K3) -> ERRO | J2: =IF(ISBLANK('LL1 Parser Table'!L3),"ERRO",'LL1 Parser Table'!L3) -> ERRO | ... BE2: =IF(ISBLANK('LL1 Parser Table'!BG3),"ERRO",'LL1 Parser Table'!BG3) -> ERRO
A3: 2 | B3: ='LL1 Parser Table'!D4 -> ProcedimentoFuncao | C3: =IF(ISBLANK('LL1 Parser Table'!E4),"ERRO",'LL1 Parser Table'!E4) -> ERRO | D3: =IF(ISBLANK('LL1 Parser Table'!F4),"ERRO",'LL1 Parser Table'!F4) -> ERRO | E3: =IF(ISBLANK('LL1 Parser Table'!G4),"ERRO",'LL1 Parser Table'!G4) -> ERRO | F3: =IF(ISBLANK('LL1 Parser Table'!H4),"ERRO",'LL1 Parser Table'!H4) -> ERRO | G3: =IF(ISBLANK('LL1 Parser Table'!I4),"ERRO",'LL1 Parser Table'!I4) -> ProcedimentoFuncao -> DeclaraProcedimento ProcedimentoFuncao | H3: =IF(ISBLANK('LL1 Parser Table'!J4),"ERRO",'LL1 Parser Table'!J4) -> ProcedimentoFuncao -> DeclaraFuncao ProcedimentoFuncao | I3: =IF(ISBLANK('LL1 Parser Table'!K4),"ERRO",'LL1 Parser Table'!K4) -> ERRO | J3: =IF(ISBLANK('LL1 Parser Table'!L4),"ERRO",'LL1 Parser Table'!L4) -> ERRO | ... BE3: =IF(ISBLANK('LL1 Parser Table'!BG4),"ERRO",'LL1 Parser Table'!BG4) -> ERRO
A4: 3 | B4: ='LL1 Parser Table'!D5 -> DeclaraProcedimento | C4: =IF(ISBLANK('LL1 Parser Table'!E5),"ERRO",'LL1 Parser Table'!E5) -> ERRO | D4: =IF(ISBLANK('LL1 Parser Table'!F5),"ERRO",'LL1 Parser Table'!F5) -> ERRO | E4: =IF(ISBLANK('LL1 Parser Table'!G5),"ERRO",'LL1 Parser Table'!G5) -> ERRO | F4: =IF(ISBLANK('LL1 Parser Table'!H5),"ERRO",'LL1 Parser Table'!H5) -> ERRO | G4: =IF(ISBLANK('LL1 Parser Table'!I5),"ERRO",'LL1 Parser Table'!I5) -> DeclaraProcedimento -> procedimento identificador Parametros ; DeclaraParametros BlocoVariaveis BlocoComandos ; | H4: =IF(ISBLANK('LL1 Parser Table'!J5),"ERRO",'LL1 Parser Table'!J5) -> ERRO | I4: =IF(ISBLANK('LL1 Parser Table'!K5),"ERRO",'LL1 Parser Table'!K5) -> ERRO | J4: =IF(ISBLANK('LL1 Parser Table'!L5),"ERRO",'LL1 Parser Table'!L5) -> ERRO | ... BE4: =IF(ISBLANK('LL1 Parser Table'!BG5),"ERRO",'LL1 Parser Table'!BG5) -> ERRO
A5: 4 | B5: ='LL1 Parser Table'!D6 -> DeclaraFuncao | C5: =IF(ISBLANK('LL1 Parser Table'!E6),"ERRO",'LL1 Parser Table'!E6) -> ERRO | D5: =IF(ISBLANK('LL1 Parser Table'!F6),"ERRO",'LL1 Parser Table'!F6) -> ERRO | E5: =IF(ISBLANK('LL1 Parser Table'!G6),"ERRO",'LL1 Parser Table'!G6) -> ERRO | F5: =IF(ISBLANK('LL1 Parser Table'!H6),"ERRO",'LL1 Parser Table'!H6) -> ERRO | G5: =IF(ISBLANK('LL1 Parser Table'!I6),"ERRO",'LL1 Parser Table'!I6) -> ERRO | H5: =IF(ISBLANK('LL1 Parser Table'!J6),"ERRO",'LL1 Parser Table'!J6) -> DeclaraFuncao -> funcao identificador Parametros : TipoBasico ; DeclaraParametros BlocoVariaveis BlocoComandos ; | I5: =IF(ISBLANK('LL1 Parser Table'!K6),"ERRO",'LL1 Parser Table'!K6) -> ERRO | J5: =IF(ISBLANK('LL1 Parser Table'!L6),"ERRO",'LL1 Parser Table'!L6) -> ERRO | ... BE5: =IF(ISBLANK('LL1 Parser Table'!BG6),"ERRO",'LL1 Parser Table'!BG6) -> ERRO
A6: 5 | B6: ='LL1 Parser Table'!D7 -> Parametros | C6: =IF(ISBLANK('LL1 Parser Table'!E7),"ERRO",'LL1 Parser Table'!E7) -> ERRO | D6: =IF(ISBLANK('LL1 Parser Table'!F7),"ERRO",'LL1 Parser Table'!F7) -> ERRO | E6: =IF(ISBLANK('LL1 Parser Table'!G7),"ERRO",'LL1 Parser Table'!G7) -> Parametros -> '' | F6: =IF(ISBLANK('LL1 Parser Table'!H7),"ERRO",'LL1 Parser Table'!H7) -> ERRO | G6: =IF(ISBLANK('LL1 Parser Table'!I7),"ERRO",'LL1 Parser Table'!I7) -> ERRO | H6: =IF(ISBLANK('LL1 Parser Table'!J7),"ERRO",'LL1 Parser Table'!J7) -> ERRO | I6: =IF(ISBLANK('LL1 Parser Table'!K7),"ERRO",'LL1 Parser Table'!K7) -> Parametros -> '' | J6: =IF(ISBLANK('LL1 Parser Table'!L7),"ERRO",'LL1 Parser Table'!L7) -> Parametros -> ( DeclaraIdentificador ) | ... BE6: =IF(ISBLANK('LL1 Parser Table'!BG7),"ERRO",'LL1 Parser Table'!BG7) -> ERRO
A7: 6 | B7: ='LL1 Parser Table'!D8 -> DeclaraParametros | C7: =IF(ISBLANK('LL1 Parser Table'!E8),"ERRO",'LL1 Parser Table'!E8) -> ERRO | D7: =IF(ISBLANK('LL1 Parser Table'!F8),"ERRO",'LL1 Parser Table'!F8) -> DeclaraParametros -> Declaracoes | E7: =IF(ISBLANK('LL1 Parser Table'!G8),"ERRO",'LL1 Parser Table'!G8) -> ERRO | F7: =IF(ISBLANK('LL1 Parser Table'!H8),"ERRO",'LL1 Parser Table'!H8) -> ERRO | G7: =IF(ISBLANK('LL1 Parser Table'!I8),"ERRO",'LL1 Parser Table'!I8) -> DeclaraParametros -> '' | H7: =IF(ISBLANK('LL1 Parser Table'!J8),"ERRO",'LL1 Parser Table'!J8) -> DeclaraParametros -> '' | I7: =IF(ISBLANK('LL1 Parser Table'!K8),"ERRO",'LL1 Parser Table'!K8) -> ERRO | J7: =IF(ISBLANK('LL1 Parser Table'!L8),"ERRO",'LL1 Parser Table'!L8) -> ERRO | ... BE7: =IF(ISBLANK('LL1 Parser Table'!BG8),"ERRO",'LL1 Parser Table'!BG8) -> ERRO
A8: 7 | B8: ='LL1 Parser Table'!D9 -> BlocoVariaveis | C8: =IF(ISBLANK('LL1 Parser Table'!E9),"ERRO",'LL1 Parser Table'!E9) -> ERRO | D8: =IF(ISBLANK('LL1 Parser Table'!F9),"ERRO",'LL1 Parser Table'!F9) -> ERRO | E8: =IF(ISBLANK('LL1 Parser Table'!G9),"ERRO",'LL1 Parser Table'!G9) -> ERRO | F8: =IF(ISBLANK('LL1 Parser Table'!H9),"ERRO",'LL1 Parser Table'!H9) -> ERRO | G8: =IF(ISBLANK('LL1 Parser Table'!I9),"ERRO",'LL1 Parser Table'!I9) -> BlocoVariaveis -> '' | H8: =IF(ISBLANK('LL1 Parser Table'!J9),"ERRO",'LL1 Parser Table'!J9) -> BlocoVariaveis -> '' | I8: =IF(ISBLANK('LL1 Parser Table'!K9),"ERRO",'LL1 Parser Table'!K9) -> ERRO | J8: =IF(ISBLANK('LL1 Parser Table'!L9),"ERRO",'LL1 Parser Table'!L9) -> ERRO | ... BE8: =IF(ISBLANK('LL1 Parser Table'!BG9),"ERRO",'LL1 Parser Table'!BG9) -> BlocoVariaveis -> ''
A9: 8 | B9: ='LL1 Parser Table'!D10 -> Declaracoes | C9: =IF(ISBLANK('LL1 Parser Table'!E10),"ERRO",'LL1 Parser Table'!E10) -> ERRO | D9: =IF(ISBLANK('LL1 Parser Table'!F10),"ERRO",'LL1 Parser Table'!F10) -> Declaracoes -> Declarations DeclaracoesBonus | E9: =IF(ISBLANK('LL1 Parser Table'!G10),"ERRO",'LL1 Parser Table'!G10) -> ERRO | F9: =IF(ISBLANK('LL1 Parser Table'!H10),"ERRO",'LL1 Parser Table'!H10) -> ERRO | G9: =IF(ISBLANK('LL1 Parser Table'!I10),"ERRO",'LL1 Parser Table'!I10) -> ERRO | H9: =IF(ISBLANK('LL1 Parser Table'!J10),"ERRO",'LL1 Parser Table'!J10) -> ERRO | I9: =IF(ISBLANK('LL1 Parser Table'!K10),"ERRO",'LL1 Parser Table'!K10) -> ERRO | J9: =IF(ISBLANK('LL1 Parser Table'!L10),"ERRO",'LL1 Parser Table'!L10) -> ERRO | ... BE9: =IF(ISBLANK('LL1 Parser Table'!BG10),"ERRO",'LL1 Parser Table'!BG10) -> ERRO
A10: 9 | B10: ='LL1 Parser Table'!D11 -> DeclaracoesBonus | C10: =IF(ISBLANK('LL1 Parser Table'!E11),"ERRO",'LL1 Parser Table'!E11) -> ERRO | D10: =IF(ISBLANK('LL1 Parser Table'!F11),"ERRO",'LL1 Parser Table'!F11) -> DeclaracoesBonus -> Declaracoes | E10: =IF(ISBLANK('LL1 Parser Table'!G11),"ERRO",'LL1 Parser Table'!G11) -> ERRO | F10: =IF(ISBLANK('LL1 Parser Table'!H11),"ERRO",'LL1 Parser Table'!H11) -> ERRO | G10: =IF(ISBLANK('LL1 Parser Table'!I11),"ERRO",'LL1 Parser Table'!I11) -> DeclaracoesBonus -> '' | H10: =IF(ISBLANK('LL1 Parser Table'!J11),"ERRO",'LL1 Parser Table'!J11) -> DeclaracoesBonus -> '' | I10: =IF(ISBLANK('LL1 Parser Table'!K11),"ERRO",'LL1 Parser Table'!K11) -> ERRO | J10: =IF(ISBLANK('LL1 Parser Table'!L11),"ERRO",'LL1 Parser Table'!L11) -> ERRO | ... BE10: =IF(ISBLANK('LL1 Parser Table'!BG11),"ERRO",'LL1 Parser Table'!BG11) -> DeclaracoesBonus -> ''
A11: 10 | B11: ='LL1 Parser Table'!D12 -> Declarations | C11: =IF(ISBLANK('LL1 Parser Table'!E12),"ERRO",'LL1 Parser Table'!E12) -> ERRO | D11: =IF(ISBLANK('LL1 Parser Table'!F12),"ERRO",'LL1 Parser Table'!F12) -> Declarations -> DeclaraVariaveis | E11: =IF(ISBLANK('LL1 Parser Table'!G12),"ERRO",'LL1 Parser Table'!G12) -> ERRO | F11: =IF(ISBLANK('LL1 Parser Table'!H12),"ERRO",'LL1 Parser Table'!H12) -> ERRO | G11: =IF(ISBLANK('LL1 Parser Table'!I12),"ERRO",'LL1 Parser Table'!I12) -> ERRO | H11: =IF(ISBLANK('LL1 Parser Table'!J12),"ERRO",'LL1 Parser Table'!J12) -> ERRO | I11: =IF(ISBLANK('LL1 Parser Table'!K12),"ERRO",'LL1 Parser Table'!K12) -> ERRO | J11: =IF(ISBLANK('LL1 Parser Table'!L12),"ERRO",'LL1 Parser Table'!L12) -> ERRO | ... BE11: =IF(ISBLANK('LL1 Parser Table'!BG12),"ERRO",'LL1 Parser Table'!BG12) -> ERRO
A12: 11 | B12: ='LL1 Parser Table'!D13 -> DeclaraTipo | C12: =IF(ISBLANK('LL1 Parser Table'!E13),"ERRO",'LL1 Parser Table'!E13) -> ERRO | D12: =IF(ISBLANK('LL1 Parser Table'!F13),"ERRO",'LL1 Parser Table'!F13) -> ERRO | E12: =IF(ISBLANK('LL1 Parser Table'!G13),"ERRO",'LL1 Parser Table'!G13) -> ERRO | F12: =IF(ISBLANK('LL1 Parser Table'!H13),"ERRO",'LL1 Parser Table'!H13) -> ERRO | G12: =IF(ISBLANK('LL1 Parser Table'!I13),"ERRO",'LL1 Parser Table'!I13) -> ERRO | H12: =IF(ISBLANK('LL1 Parser Table'!J13),"ERRO",'LL1 Parser Table'!J13) -> ERRO | I12: =IF(ISBLANK('LL1 Parser Table'!K13),"ERRO",'LL1 Parser Table'!K13) -> ERRO | J12: =IF(ISBLANK('LL1 Parser Table'!L13),"ERRO",'LL1 Parser Table'!L13) -> ERRO | ... BE12: =IF(ISBLANK('LL1 Parser Table'!BG13),"ERRO",'LL1 Parser Table'!BG13) -> ERRO
A13: 12 | B13: ='LL1 Parser Table'!D14 -> DeclaraVariaveis | C13: =IF(ISBLANK('LL1 Parser Table'!E14),"ERRO",'LL1 Parser Table'!E14) -> ERRO | D13: =IF(ISBLANK('LL1 Parser Table'!F14),"ERRO",'LL1 Parser Table'!F14) -> DeclaraVariaveis -> TipoBasico : DeclaraIdentificador ; | E13: =IF(ISBLANK('LL1 Parser Table'!G14),"ERRO",'LL1 Parser Table'!G14) -> ERRO | F13: =IF(ISBLANK('LL1 Parser Table'!H14),"ERRO",'LL1 Parser Table'!H14) -> ERRO | G13: =IF(ISBLANK('LL1 Parser Table'!I14),"ERRO",'LL1 Parser Table'!I14) -> ERRO | H13: =IF(ISBLANK('LL1 Parser Table'!J14),"ERRO",'LL1 Parser Table'!J14) -> ERRO | I13: =IF(ISBLANK('LL1 Parser Table'!K14),"ERRO",'LL1 Parser Table'!K14) -> ERRO | J13: =IF(ISBLANK('LL1 Parser Table'!L14),"ERRO",'LL1 Parser Table'!L14) -> ERRO | ... BE13: =IF(ISBLANK('LL1 Parser Table'!BG14),"ERRO",'LL1 Parser Table'!BG14) -> ERRO
... A39: 38 | B39: ='LL1 Parser Table'!D40 -> ExprIterBonus | C39: =IF(ISBLANK('LL1 Parser Table'!E40),"ERRO",'LL1 Parser Table'!E40) -> ERRO | D39: =IF(ISBLANK('LL1 Parser Table'!F40),"ERRO",'LL1 Parser Table'!F40) -> ERRO | E39: =IF(ISBLANK('LL1 Parser Table'!G40),"ERRO",'LL1 Parser Table'!G40) -> ERRO | F39: =IF(ISBLANK('LL1 Parser Table'!H40),"ERRO",'LL1 Parser Table'!H40) -> ERRO | G39: =IF(ISBLANK('LL1 Parser Table'!I40),"ERRO",'LL1 Parser Table'!I40) -> ERRO | H39: =IF(ISBLANK('LL1 Parser Table'!J40),"ERRO",'LL1 Parser Table'!J40) -> ERRO | I39: =IF(ISBLANK('LL1 Parser Table'!K40),"ERRO",'LL1 Parser Table'!K40) -> ERRO | J39: =IF(ISBLANK('LL1 Parser Table'!L40),"ERRO",'LL1 Parser Table'!L40) -> ERRO | ... BE39: =IF(ISBLANK('LL1 Parser Table'!BG40),"ERRO",'LL1 Parser Table'!BG40) -> ERRO

Sheet Labels
B2: Nonterminal | C2: COD | E2: TERMINAL | F2: COD | H2: Producao | I2: COD | N2: algoritmo | O2: identificador | P2: ; | Q2: . | R2: procedimento | S2: funcao | T2: : | U2: ( | V2: ) | W2: variaveis | X2: tipo | Y2: = | Z2: [ | AA2: ] | AB2: , | AC2: vetor | AD2: matriz | AE2: numero_inteiro | AF2: inteiro | AG2: real | AH2: caractere | AI2: logico | AJ2: inicio | AK2: fim | AL2: <- | AM2: se | AN2: entao | AO2: senao | AP2: enquanto | AQ2: faca | AR2: para | AS2: de | AT2: ate | AU2: passo | AV2: repita | AW2: leia | AX2: imprima | AY2: <> | AZ2: < | BA2: <= | BB2: >= | BC2: > | BD2: + | BE2: - | BF2: ou | BG2: * | BH2: / | BI2: div | BJ2: e | BK2: nao | BL2: numero_real | BM2: TRUE | BN2: FALSE | BO2: string | BP2: $
B3: Programa | C3: 1 | E3: algoritmo | F3: 1 | H3: Programa -> algoritmo identificador ; BlocoVariaveis ProcedimentoFuncao BlocoComandos . | I3: 1
B4: ProcedimentoFuncao | C4: 2 | E4: identificador | F4: 2 | H4: ProcedimentoFuncao -> DeclaraProcedimento ProcedimentoFuncao | I4: 2
B5: DeclaraProcedimento | C5: 3 | E5: ; | F5: 3 | H5: ProcedimentoFuncao -> DeclaraFuncao ProcedimentoFuncao | I5: 3
B6: DeclaraFuncao | C6: 4 | E6: . | F6: 4 | H6: ProcedimentoFuncao -> '' | I6: 4
B7: Parametros | C7: 5 | E7: procedimento | F7: 5 | H7: DeclaraProcedimento -> procedimento identificador Parametros ; DeclaraParametros BlocoVariaveis BlocoComandos ; | I7: 5
B8: DeclaraParametros | C8: 6 | E8: funcao | F8: 6 | H8: DeclaraFuncao -> funcao identificador Parametros : TipoBasico ; DeclaraParametros BlocoVariaveis BlocoComandos ; | I8: 6
B9: BlocoVariaveis | C9: 7 | E9: : | F9: 7 | H9: Parametros -> ( DeclaraIdentificador ) | I9: 7
B10: Declaracoes | C10: 8 | E10: ( | F10: 8 | H10: Parametros -> '' | I10: 8
B11: DeclaracoesBonus | C11: 9 | E11: ) | F11: 9 | H11: DeclaraParametros -> Declaracoes | I11: 9
B12: Declarations | C12: 10 | E12: variaveis | F12: 10 | H12: DeclaraParametros -> '' | I12: 10
B13: DeclaraTipo | C13: 11 | E13: tipo | F13: 11 | H13: BlocoVariaveis -> variaveis Declaracoes | I13: 11
B14: DeclaraVariaveis | C14: 12 | E14: = | F14: 12 | H14: BlocoVariaveis -> '' | I14: 12
... B40: ExprIterBonus | C40: 38 | E40: <> | F40: 38 | H40: CommandsIdentifier -> '' | I40: 38
E41: < | F41: 39 | H41: CommandsIdentifier -> ( ExprIter ) | I41: 39
E42: <= | F42: 40 | H42: CommandsIdentifier -> <- Expressao | I42: 40
E43: >= | F43: 41 | H43: CommandsIdentifier -> [ ExprIter ] <- Expressao | I43: 41
E44: > | F44: 42 | H44: Comandos -> se Expressao entao ListaComandos ElseIf fim se | I44: 42
B45: =UPPER(B3) -> PROGRAMA | C45: =C3 -> 1 | E45: + | F45: 43 | H45: ElseIf -> senao ListaComandos | I45: 43
B46: =UPPER(B4) -> PROCEDIMENTOFUNCAO | C46: =C4 -> 2 | E46: - | F46: 44 | H46: ElseIf -> '' | I46: 44
B47: =UPPER(B5) -> DECLARAPROCEDIMENTO | C47: =C5 -> 3 | E47: ou | F47: 45 | H47: Comandos -> enquanto Expressao faca ListaComandos fim enquanto | I47: 45
B48: =UPPER(B6) -> DECLARAFUNCAO | C48: =C6 -> 4 | E48: * | F48: 46 | H48: Comandos -> para identificador de Expressao ate Expressao StepFor faca ListaComandos fim para | I48: 46
B49: =UPPER(B7) -> PARAMETROS | C49: =C7 -> 5 | E49: / | F49: 47 | H49: StepFor -> passo Expressao | I49: 47
B50: =UPPER(B8) -> DECLARAPARAMETROS | C50: =C8 -> 6 | E50: div | F50: 48 | H50: StepFor -> '' | I50: 48
B51: =UPPER(B9) -> BLOCOVARIAVEIS | C51: =C9 -> 7 | E51: e | F51: 49 | H51: Comandos -> repita ListaComandos ate Expressao | I51: 49
B52: =UPPER(B10) -> DECLARACOES | C52: =C10 -> 8 | E52: nao | F52: 50 | H52: Comandos -> leia ( Variavel ) | I52: 50
B53: =UPPER(B11) -> DECLARACOESBONUS | C53: =C11 -> 9 | E53: numero_real | F53: 51 | H53: Comandos -> imprima ( ExprIter ) | I53: 51
B54: =UPPER(B12) -> DECLARATIONS | C54: =C12 -> 10 | E54: TRUE | F54: 52 | H54: Expressao -> ExpressaoSimples ExpressaoNew | I54: 52
B55: =UPPER(B13) -> DECLARATIPO | C55: =C13 -> 11 | E55: FALSE | F55: 53 | H55: ExpressaoNew -> = ExpressaoSimples ExpressaoNew | I55: 53
B56: =UPPER(B14) -> DECLARAVARIAVEIS | C56: =C14 -> 12 | E56: string | F56: 54 | H56: ExpressaoNew -> <> ExpressaoSimples ExpressaoNew | I56: 54
B57: =UPPER(B15) -> DECLARAIDENTIFICADOR | C57: =C15 -> 13 | E57: $ | F57: 55 | H57: ExpressaoNew -> < ExpressaoSimples ExpressaoNew | I57: 55
B58: =UPPER(B16) -> DECLARAIDENTIFICADORBONUS | C58: =C16 -> 14 | H58: ExpressaoNew -> <= ExpressaoSimples ExpressaoNew | I58: 56
B59: =UPPER(B17) -> VETORMATRIZ | C59: =C17 -> 15 | H59: ExpressaoNew -> >= ExpressaoSimples ExpressaoNew | I59: 57
B60: =UPPER(B18) -> DIMENSAO | C60: =C18 -> 16 | H60: ExpressaoNew -> > ExpressaoSimples ExpressaoNew | I60: 58
B61: =UPPER(B19) -> DIMENSAOBONUS | C61: =C19 -> 17 | H61: ExpressaoNew -> '' | I61: 59
B62: =UPPER(B20) -> TIPOBASICO | C62: =C20 -> 18 | H62: ExpressaoSimples -> Signal Termo ExpressaoSimplesNew | I62: 60
B63: =UPPER(B21) -> BLOCOCOMANDOS | C63: =C21 -> 19 | H63: Signal -> + | I63: 61
B64: =UPPER(B22) -> LISTACOMANDOS | C64: =C22 -> 20 | H64: Signal -> - | I64: 62
B65: =UPPER(B23) -> LISTACOMANDOSBONUS | C65: =C23 -> 21 | H65: Signal -> '' | I65: 63
B66: =UPPER(B24) -> COMANDOS | C66: =C24 -> 22 | H66: ExpressaoSimplesNew -> + Termo ExpressaoSimplesNew | I66: 64
...

Sheet Format2
C1: {=TRANSPOSE(Labels!E3:E57)} -> algoritmo | D1: identificador | E1: ; | F1: . | G1: procedimento | H1: funcao | I1: : | J1: ( | K1: ) | L1: variaveis | M1: tipo | N1: = | O1: [ | P1: ] | Q1: , | R1: vetor | S1: matriz | T1: numero_inteiro | U1: inteiro | V1: real | W1: caractere | X1: logico | Y1: inicio | Z1: fim | AA1: <- | AB1: se | AC1: entao | AD1: senao | AE1: enquanto | AF1: faca | AG1: para | AH1: de | AI1: ate | AJ1: passo | AK1: repita | AL1: leia | AM1: imprima | AN1: <> | AO1: < | AP1: <= | AQ1: >= | AR1: > | AS1: + | AT1: - | AU1: ou | AV1: * | AW1: / | AX1: div | AY1: e | AZ1: nao | BA1: numero_real | BB1: TRUE | BC1: FALSE | BD1: string | BE1: $
C2: =VLOOKUP(Format1!C1,Labels!$E$3:$F$57,2,FALSE) -> 1 | D2: =VLOOKUP(Format1!D1,Labels!$E$3:$F$57,2,FALSE) -> 2 | E2: =VLOOKUP(Format1!E1,Labels!$E$3:$F$57,2,FALSE) -> 3 | F2: =VLOOKUP(Format1!F1,Labels!$E$3:$F$57,2,FALSE) -> 4 | G2: =VLOOKUP(Format1!G1,Labels!$E$3:$F$57,2,FALSE) -> 5 | H2: =VLOOKUP(Format1!H1,Labels!$E$3:$F$57,2,FALSE) -> 6 | I2: =VLOOKUP(Format1!I1,Labels!$E$3:$F$57,2,FALSE) -> 7 | J2: =VLOOKUP(Format1!J1,Labels!$E$3:$F$57,2,FALSE) -> 8 | ... AU2: =VLOOKUP(Format1!AU1,Labels!$E$3:$F$57,2,FALSE) -> 45 | AV2: 46 | AW2: =VLOOKUP(Format1!AW1,Labels!$E$3:$F$57,2,FALSE) -> 47 | AX2: =VLOOKUP(Format1!AX1,Labels!$E$3:$F$57,2,FALSE) -> 48 | AY2: =VLOOKUP(Format1!AY1,Labels!$E$3:$F$57,2,FALSE) -> 49 | AZ2: =VLOOKUP(Format1!AZ1,Labels!$E$3:$F$57,2,FALSE) -> 50 | BA2: =VLOOKUP(Format1!BA1,Labels!$E$3:$F$57,2,FALSE) -> 51 | BB2: =VLOOKUP(Format1!BB1,Labels!$E$3:$F$57,2,FALSE) -> 52 | BC2: =VLOOKUP(Format1!BC1,Labels!$E$3:$F$57,2,FALSE) -> 53 | BD2: =VLOOKUP(Format1!BD1,Labels!$E$3:$F$57,2,FALSE) -> 54 | BE2: =VLOOKUP(Format1!BE1,Labels!$E$3:$F$57,2,FALSE) -> 55
A3: {=Labels!B3:C40} -> Programa | B3: 1 | C3: =VLOOKUP(Format1!C2,Labels!$H$3:$I$92,2,FALSE) + 100 -> 101 | D3: =VLOOKUP(Format1!D2,Labels!$H$3:$I$92,2,FALSE) + 100 -> 100 | E3: =VLOOKUP(Format1!E2,Labels!$H$3:$I$92,2,FALSE) + 100 -> 100 | F3: =VLOOKUP(Format1!F2,Labels!$H$3:$I$92,2,FALSE) + 100 -> 100 | G3: =VLOOKUP(Format1!G2,Labels!$H$3:$I$92,2,FALSE) + 100 -> 100 | H3: =VLOOKUP(Format1!H2,Labels!$H$3:$I$92,2,FALSE) + 100 -> 100 | I3: =VLOOKUP(Format1!I2,Labels!$H$3:$I$92,2,FALSE) + 100 -> 100 | J3: =VLOOKUP(Format1!J2,Labels!$H$3:$I$92,2,FALSE) + 100 -> 100 | ... BE3: =VLOOKUP(Format1!BE2,Labels!$H$3:$I$92,2,FALSE) + 100 -> 100
A4: ProcedimentoFuncao | B4: 2 | C4: =VLOOKUP(Format1!C3,Labels!$H$3:$I$92,2,FALSE) + 100 -> 100 | D4: =VLOOKUP(Format1!D3,Labels!$H$3:$I$92,2,FALSE) + 100 -> 100 | E4: =VLOOKUP(Format1!E3,Labels!$H$3:$I$92,2,FALSE) + 100 -> 100 | F4: =VLOOKUP(Format1!F3,Labels!$H$3:$I$92,2,FALSE) + 100 -> 100 | G4: =VLOOKUP(Format1!G3,Labels!$H$3:$I$92,2,FALSE) + 100 -> 102 | H4: =VLOOKUP(Format1!H3,Labels!$H$3:$I$92,2,FALSE) + 100 -> 103 | I4: =VLOOKUP(Format1!I3,Labels!$H$3:$I$92,2,FALSE) + 100 -> 100 | J4: =VLOOKUP(Format1!J3,Labels!$H$3:$I$92,2,FALSE) + 100 -> 100 | ... BE4: =VLOOKUP(Format1!BE3,Labels!$H$3:$I$92,2,FALSE) + 100 -> 100
A5: DeclaraProcedimento | B5: 3 | C5: =VLOOKUP(Format1!C4,Labels!$H$3:$I$92,2,FALSE) + 100 -> 100 | D5: =VLOOKUP(Format1!D4,Labels!$H$3:$I$92,2,FALSE) + 100 -> 100 | E5: =VLOOKUP(Format1!E4,Labels!$H$3:$I$92,2,FALSE) + 100 -> 100 | F5: =VLOOKUP(Format1!F4,Labels!$H$3:$I$92,2,FALSE) + 100 -> 100 | G5: =VLOOKUP(Format1!G4,Labels!$H$3:$I$92,2,FALSE) + 100 -> 105 | H5: =VLOOKUP(Format1!H4,Labels!$H$3:$I$92,2,FALSE) + 100 -> 100 | I5: =VLOOKUP(Format1!I4,Labels!$H$3:$I$92,2,FALSE) + 100 -> 100 | J5: =VLOOKUP(Format1!J4,Labels!$H$3:$I$92,2,FALSE) + 100 -> 100 | ... BE5: =VLOOKUP(Format1!BE4,Labels!$H$3:$I$92,2,FALSE) + 100 -> 100
A6: DeclaraFuncao | B6: 4 | C6: =VLOOKUP(Format1!C5,Labels!$H$3:$I$92,2,FALSE) + 100 -> 100 | D6: =VLOOKUP(Format1!D5,Labels!$H$3:$I$92,2,FALSE) + 100 -> 100 | E6: =VLOOKUP(Format1!E5,Labels!$H$3:$I$92,2,FALSE) + 100 -> 100 | F6: =VLOOKUP(Format1!F5,Labels!$H$3:$I$92,2,FALSE) + 100 -> 100 | G6: =VLOOKUP(Format1!G5,Labels!$H$3:$I$92,2,FALSE) + 100 -> 100 | H6: =VLOOKUP(Format1!H5,Labels!$H$3:$I$92,2,FALSE) + 100 -> 106 | I6: =VLOOKUP(Format1!I5,Labels!$H$3:$I$92,2,FALSE) + 100 -> 100 | J6: =VLOOKUP(Format1!J5,Labels!$H$3:$I$92,2,FALSE) + 100 -> 100 | ... BE6: =VLOOKUP(Format1!BE5,Labels!$H$3:$I$92,2,FALSE) + 100 -> 100
A7: Parametros | B7: 5 | C7: =VLOOKUP(Format1!C6,Labels!$H$3:$I$92,2,FALSE) + 100 -> 100 | D7: =VLOOKUP(Format1!D6,Labels!$H$3:$I$92,2,FALSE) + 100 -> 100 | E7: =VLOOKUP(Format1!E6,Labels!$H$3:$I$92,2,FALSE) + 100 -> 108 | F7: =VLOOKUP(Format1!F6,Labels!$H$3:$I$92,2,FALSE) + 100 -> 100 | G7: =VLOOKUP(Format1!G6,Labels!$H$3:$I$92,2,FALSE) + 100 -> 100 | H7: =VLOOKUP(Format1!H6,Labels!$H$3:$I$92,2,FALSE) + 100 -> 100 | I7: =VLOOKUP(Format1!I6,Labels!$H$3:$I$92,2,FALSE) + 100 -> 108 | J7: =VLOOKUP(Format1!J6,Labels!$H$3:$I$92,2,FALSE) + 100 -> 107 | ... BE7: =VLOOKUP(Format1!BE6,Labels!$H$3:$I$92,2,FALSE) + 100 -> 100
A8: DeclaraParametros | B8: 6 | C8: =VLOOKUP(Format1!C7,Labels!$H$3:$I$92,2,FALSE) + 100 -> 100 | D8: =VLOOKUP(Format1!D7,Labels!$H$3:$I$92,2,FALSE) + 100 -> 109 | E8: =VLOOKUP(Format1!E7,Labels!$H$3:$I$92,2,FALSE) + 100 -> 100 | F8: =VLOOKUP(Format1!F7,Labels!$H$3:$I$92,2,FALSE) + 100 -> 100 | G8: =VLOOKUP(Format1!G7,Labels!$H$3:$I$92,2,FALSE) + 100 -> 110 | H8: =VLOOKUP(Format1!H7,Labels!$H$3:$I$92,2,FALSE) + 100 -> 110 | I8: =VLOOKUP(Format1!I7,Labels!$H$3:$I$92,2,FALSE) + 100 -> 100 | J8: =VLOOKUP(Format1!J7,Labels!$H$3:$I$92,2,FALSE) + 100 -> 100 | ... BE8: =VLOOKUP(Format1!BE7,Labels!$H$3:$I$92,2,FALSE) + 100 -> 100
A9: BlocoVariaveis | B9: 7 | C9: =VLOOKUP(Format1!C8,Labels!$H$3:$I$92,2,FALSE) + 100 -> 100 | D9: =VLOOKUP(Format1!D8,Labels!$H$3:$I$92,2,FALSE) + 100 -> 100 | E9: =VLOOKUP(Format1!E8,Labels!$H$3:$I$92,2,FALSE) + 100 -> 100 | F9: =VLOOKUP(Format1!F8,Labels!$H$3:$I$92,2,FALSE) + 100 -> 100 | G9: =VLOOKUP(Format1!G8,Labels!$H$3:$I$92,2,FALSE) + 100 -> 112 | H9: =VLOOKUP(Format1!H8,Labels!$H$3:$I$92,2,FALSE) + 100 -> 112 | I9: =VLOOKUP(Format1!I8,Labels!$H$3:$I$92,2,FALSE) + 100 -> 100 | J9: =VLOOKUP(Format1!J8,Labels!$H$3:$I$92,2,FALSE) + 100 -> 100 | ... BE9: =VLOOKUP(Format1!BE8,Labels!$H$3:$I$92,2,FALSE) + 100 -> 112
A10: Declaracoes | B10: 8 | C10: =VLOOKUP(Format1!C9,Labels!$H$3:$I$92,2,FALSE) + 100 -> 100 | D10: =VLOOKUP(Format1!D9,Labels!$H$3:$I$92,2,FALSE) + 100 -> 113 | E10: =VLOOKUP(Format1!E9,Labels!$H$3:$I$92,2,FALSE) + 100 -> 100 | F10: =VLOOKUP(Format1!F9,Labels!$H$3:$I$92,2,FALSE) + 100 -> 100 | G10: =VLOOKUP(Format1!G9,Labels!$H$3:$I$92,2,FALSE) + 100 -> 100 | H10: =VLOOKUP(Format1!H9,Labels!$H$3:$I$92,2,FALSE) + 100 -> 100 | I10: =VLOOKUP(Format1!I9,Labels!$H$3:$I$92,2,FALSE) + 100 -> 100 | J10: =VLOOKUP(Format1!J9,Labels!$H$3:$I$92,2,FALSE) + 100 -> 100 | ... BE10: =VLOOKUP(Format1!BE9,Labels!$H$3:$I$92,2,FALSE) + 100 -> 100
A11: DeclaracoesBonus | B11: 9 | C11: =VLOOKUP(Format1!C10,Labels!$H$3:$I$92,2,FALSE) + 100 -> 100 | D11: =VLOOKUP(Format1!D10,Labels!$H$3:$I$92,2,FALSE) + 100 -> 114 | E11: =VLOOKUP(Format1!E10,Labels!$H$3:$I$92,2,FALSE) + 100 -> 100 | F11: =VLOOKUP(Format1!F10,Labels!$H$3:$I$92,2,FALSE) + 100 -> 100 | G11: =VLOOKUP(Format1!G10,Labels!$H$3:$I$92,2,FALSE) + 100 -> 115 | H11: =VLOOKUP(Format1!H10,Labels!$H$3:$I$92,2,FALSE) + 100 -> 115 | I11: =VLOOKUP(Format1!I10,Labels!$H$3:$I$92,2,FALSE) + 100 -> 100 | J11: =VLOOKUP(Format1!J10,Labels!$H$3:$I$92,2,FALSE) + 100 -> 100 | ... BE11: =VLOOKUP(Format1!BE10,Labels!$H$3:$I$92,2,FALSE) + 100 -> 115
A12: Declarations | B12: 10 | C12: =VLOOKUP(Format1!C11,Labels!$H$3:$I$92,2,FALSE) + 100 -> 100 | D12: =VLOOKUP(Format1!D11,Labels!$H$3:$I$92,2,FALSE) + 100 -> 117 | E12: =VLOOKUP(Format1!E11,Labels!$H$3:$I$92,2,FALSE) + 100 -> 100 | F12: =VLOOKUP(Format1!F11,Labels!$H$3:$I$92,2,FALSE) + 100 -> 100 | G12: =VLOOKUP(Format1!G11,Labels!$H$3:$I$92,2,FALSE) + 100 -> 100 | H12: =VLOOKUP(Format1!H11,Labels!$H$3:$I$92,2,FALSE) + 100 -> 100 | I12: =VLOOKUP(Format1!I11,Labels!$H$3:$I$92,2,FALSE) + 100 -> 100 | J12: =VLOOKUP(Format1!J11,Labels!$H$3:$I$92,2,FALSE) + 100 -> 100 | ... BE12: =VLOOKUP(Format1!BE11,Labels!$H$3:$I$92,2,FALSE) + 100 -> 100
A13: DeclaraTipo | B13: 11 | C13: =VLOOKUP(Format1!C12,Labels!$H$3:$I$92,2,FALSE) + 100 -> 100 | D13: =VLOOKUP(Format1!D12,Labels!$H$3:$I$92,2,FALSE) + 100 -> 100 | E13: =VLOOKUP(Format1!E12,Labels!$H$3:$I$92,2,FALSE) + 100 -> 100 | F13: =VLOOKUP(Format1!F12,Labels!$H$3:$I$92,2,FALSE) + 100 -> 100 | G13: =VLOOKUP(Format1!G12,Labels!$H$3:$I$92,2,FALSE) + 100 -> 100 | H13: =VLOOKUP(Format1!H12,Labels!$H$3:$I$92,2,FALSE) + 100 -> 100 | I13: =VLOOKUP(Format1!I12,Labels!$H$3:$I$92,2,FALSE) + 100 -> 100 | J13: =VLOOKUP(Format1!J12,Labels!$H$3:$I$92,2,FALSE) + 100 -> 100 | ... BE13: =VLOOKUP(Format1!BE12,Labels!$H$3:$I$92,2,FALSE) + 100 -> 100
A14: DeclaraVariaveis | B14: 12 | C14: =VLOOKUP(Format1!C13,Labels!$H$3:$I$92,2,FALSE) + 100 -> 100 | D14: =VLOOKUP(Format1!D13,Labels!$H$3:$I$92,2,FALSE) + 100 -> 119 | E14: =VLOOKUP(Format1!E13,Labels!$H$3:$I$92,2,FALSE) + 100 -> 100 | F14: =VLOOKUP(Format1!F13,Labels!$H$3:$I$92,2,FALSE) + 100 -> 100 | G14: =VLOOKUP(Format1!G13,Labels!$H$3:$I$92,2,FALSE) + 100 -> 100 | H14: =VLOOKUP(Format1!H13,Labels!$H$3:$I$92,2,FALSE) + 100 -> 100 | I14: =VLOOKUP(Format1!I13,Labels!$H$3:$I$92,2,FALSE) + 100 -> 100 | J14: =VLOOKUP(Format1!J13,Labels!$H$3:$I$92,2,FALSE) + 100 -> 100 | ... BE14: =VLOOKUP(Format1!BE13,Labels!$H$3:$I$92,2,FALSE) + 100 -> 100
A15: DeclaraIdentificador | B15: 13 | C15: =VLOOKUP(Format1!C14,Labels!$H$3:$I$92,2,FALSE) + 100 -> 100 | D15: =VLOOKUP(Format1!D14,Labels!$H$3:$I$92,2,FALSE) + 100 -> 120 | E15: =VLOOKUP(Format1!E14,Labels!$H$3:$I$92,2,FALSE) + 100 -> 100 | F15: =VLOOKUP(Format1!F14,Labels!$H$3:$I$92,2,FALSE) + 100 -> 100 | G15: =VLOOKUP(Format1!G14,Labels!$H$3:$I$92,2,FALSE) + 100 -> 100 | H15: =VLOOKUP(Format1!H14,Labels!$H$3:$I$92,2,FALSE) + 100 -> 100 | I15: =VLOOKUP(Format1!I14,Labels!$H$3:$I$92,2,FALSE) + 100 -> 100 | J15: =VLOOKUP(Format1!J14,Labels!$H$3:$I$92,2,FALSE) + 100 -> 100 | ... BE15: =VLOOKUP(Format1!BE14,Labels!$H$3:$I$92,2,FALSE) + 100 -> 100
... A40: ExprIterBonus | B40: 38 | C40: =VLOOKUP(Format1!C39,Labels!$H$3:$I$92,2,FALSE) + 100 -> 100 | D40: =VLOOKUP(Format1!D39,Labels!$H$3:$I$92,2,FALSE) + 100 -> 100 | E40: =VLOOKUP(Format1!E39,Labels!$H$3:$I$92,2,FALSE) + 100 -> 100 | F40: =VLOOKUP(Format1!F39,Labels!$H$3:$I$92,2,FALSE) + 100 -> 100 | G40: =VLOOKUP(Format1!G39,Labels!$H$3:$I$92,2,FALSE) + 100 -> 100 | H40: =VLOOKUP(Format1!H39,Labels!$H$3:$I$92,2,FALSE) + 100 -> 100 | I40: =VLOOKUP(Format1!I39,Labels!$H$3:$I$92,2,FALSE) + 100 -> 100 | J40: =VLOOKUP(Format1!J39,Labels!$H$3:$I$92,2,FALSE) + 100 -> 100 | ... BE40: =VLOOKUP(Format1!BE39,Labels!$H$3:$I$92,2,FALSE) + 100 -> 100
